Workbook

Sheet Resumen
A1: Oportunidad digital – Miami-Dade y Broward
A2: Empresas establecidas sin web o con web obsoleta. Tablas dinámicas en hojas TD_*. Septiembre 2026.
A4: Indicadores | D4: Por condado | G4: Mercado
A5: Prospectos identificados | B5: =COUNTA(Prospectos!B5:B99) -> 95 | D5: Miami-Dade | E5: =COUNTIF(Prospectos!$E$5:$E$99,D5) -> 64 | G5: Establecimientos Miami-Dade (CBP 2023) | H5: 98394
A6: Sin sitio web | B6: =COUNTIF(Prospectos!$J$5:$J$99,"Sin sitio web") -> 15 | D6: Broward | E6: =COUNTIF(Prospectos!$E$5:$E$99,D6) -> 31 | G6: Establecimientos Broward (CBP 2022) | H6: 67274
A7: Sitio obsoleto / desordenado | B7: =COUNTIF(Prospectos!$J$5:$J$99,"Sitio obsoleto")+COUNTIF(Prospectos!$J$5:$J$99,"Presencia desordenada") -> 11 | G7: Solicitudes de negocio FL 2024 | H7: 634000
A8: Brecha confirmada (%) | B8: =IF(B5=0,0,(B6+B7)/B5) -> 0.27368421 | D8: Con brecha en Miami-Dade | E8: =COUNTIFS(Prospectos!$E$5:$E$99,"Miami-Dade",Prospectos!$J$5:$J$99,"Sin sitio web")+COUNTIFS(Prospectos!$E$5:$E$99,"Miami-Dade",Prospectos!$J$5:$J$99,"Sitio obsoleto")+COUNTIFS(Prospectos!$E$5:$E$99,"Miami-Dade",Prospectos!$J$5:$J$99,"Presencia desordenada") -> 14 | G8: Pymes EE.UU. sin web (Clutch 2025) | H8: 0.17
A9: Prioridad A | B9: =COUNTIF(Prospectos!$U$5:$U$99,"A") -> 13 | D9: Con brecha en Broward | E9: =COUNTIFS(Prospectos!$E$5:$E$99,"Broward",Prospectos!$J$5:$J$99,"Sin sitio web")+COUNTIFS(Prospectos!$E$5:$E$99,"Broward",Prospectos!$J$5:$J$99,"Sitio obsoleto")+COUNTIFS(Prospectos!$E$5:$E$99,"Broward",Prospectos!$J$5:$J$99,"Presencia desordenada") -> 12 | G9: Demandas ADA Title III FL 2025 | H9: 1823
A10: Pendientes de verificar web | B10: =COUNTIF(Prospectos!$J$5:$J$99,"No verificado") -> 50 | G10: CPC promedio Google Ads 2025 | H10: 5.26
A13: Hallazgos clave
A14: 1. Medley, Hialeah y Doral concentran la brecha más valiosa: manufactura, transporte y distribución B2B con 10–100 empleados, décadas operando y presencia solo en directorios (BBB, Manta, Yelp).
A15: 2. Transporte de carga (flotas de 55–66 camiones en Medley) y contratistas (Construct Group ~100 empleados con plantilla web sin editar) = prioridad A: ticket alto y competidores ya digitalizados.
A16: 3. En la náutica de Fort Lauderdale la mayoría ya tiene web. La oportunidad está en talleres antiguos (desde 1976–1999) con solo BBB/Yelp y en rediseño de sitios básicos.
A17: 4. HVAC, plomería y administración de propiedades (Davie, Sunrise, North Miami) muestran alta proporción de negocios sin dominio propio y CPL de Google Ads de $76–100: fácil demostrar ROI.
A18: 5. Florida es 2.º estado en demandas ADA (1,823 en 2025): una web accesible (WCAG 2.2 AA) es un argumento de venta con riesgo legal cuantificable.
A19: 6. Canal de contacto recomendado: email B2B 1 a 1 (CAN-SPAM) + visita presencial. Evitar llamadas/SMS automatizados (FTSA: $500–1,500 por violación).
A20: 7. Escalamiento: datasets abiertos BTR de Miami-Dade/Broward + SFTP de Sunbiz permiten pasar de ~95 a miles de prospectos con verificación automática de dominio.
A22: Hojas: Prospectos · TD_Area_Web · TD_Industria_Web · TD_Legal_Prioridad · TD_Redes · Oportunidad_Industria · Macro_Areas · Adopcion_Digital · Google_Ads · Legal_Cumplimiento · Parametros · Metodologia

Sheet Prospectos
A1: Prospectos: empresas con brecha digital
A2: Fuente por fila. Columnas azules/amarillas = completar tras verificación en Sunbiz y Google Maps.
A4: ID | B4: Empresa | C4: Municipio | D4: Barrio/zona | E4: Condado | F4: Sector (detalle) | G4: NAICS | H4: Industria (NAICS) | I4: Forma legal | J4: Estado web | K4: Redes sociales | L4: Tiene redes | M4: Evidencia | N4: Fuente | O4: Empleados (est.) | P4: Año fundación | Q4: Peso web | R4: Peso sector | S4: Señal tamaño | T4: Puntaje | U4: Prioridad | V4: Estado Sunbiz | W4: Próximo paso
A5: P001 | B5: Jonel Knitting Mills Inc | C5: Hialeah | E5: Miami-Dade | F5: Manufactura textil (tejidos de punto) | G5: 31 | H5: 31-33 Manufactura | I5: Inc | J5: Sin sitio web | K5: Ninguna encontrada | L5: No | M5: Manta: fundada 1987, ~25 empleados; sin web ni Facebook | N5: https://www.manta.com/c/mmn1h0x/jonel-knitting-mills-inc | O5: 25 | P5: 1987 | Q5: =IFERROR(VLOOKUP(J5,Parametros!$A$5:$B$9,2,FALSE()),0) -> 3 | R5: =IFERROR(VLOOKUP(H5,Parametros!$D$5:$E$16,2,FALSE()),1) -> 2 | S5: =IF(OR(N(O5)>=Parametros!$H$9,AND(N(P5)>0,N(P5)<=Parametros!$H$10)),1,0) -> 1 | T5: =Q5+R5+S5 -> 6 | U5: =IF(OR(V5="Inactive",V5="No encontrada"),"Descartada",IF(AND(T5>=Parametros!$H$5,S5=1),"A",IF(T5>=Parametros!$H$6,"B","C"))) -> A | V5: Pendiente
A6: P002 | B6: Steel Works Rebar Fabricators LLC | C6: Medley | E6: Miami-Dade | F6: Fabricación de acero/varilla | G6: 33 | H6: 31-33 Manufactura | I6: LLC | J6: Sin sitio web | K6: Facebook | L6: Sí | M6: Est. 2007, 10-19 empleados; solo directorios y Facebook | N6: https://www.manta.com/c/mmcwr0p/steel-works-rebar-fabricators-llc | O6: 10 | P6: 2007 | Q6: =IFERROR(VLOOKUP(J6,Parametros!$A$5:$B$9,2,FALSE()),0) -> 3 | R6: =IFERROR(VLOOKUP(H6,Parametros!$D$5:$E$16,2,FALSE()),1) -> 2 | S6: =IF(OR(N(O6)>=Parametros!$H$9,AND(N(P6)>0,N(P6)<=Parametros!$H$10)),1,0) -> 1 | T6: =Q6+R6+S6 -> 6 | U6: =IF(OR(V6="Inactive",V6="No encontrada"),"Descartada",IF(AND(T6>=Parametros!$H$5,S6=1),"A",IF(T6>=Parametros!$H$6,"B","C"))) -> A | V6: Pendiente
A7: P003 | B7: All Welding and Machine Shop Inc | C7: Medley | E7: Miami-Dade | F7: Soldadura/taller industrial | G7: 33 | H7: 31-33 Manufactura | I7: Inc | J7: Sin sitio web | K7: Ninguna encontrada | L7: No | M7: Solo YellowPages, Superpages, Manta, Waze | N7: https://www.yellowpages.com/medley-fl/mip/all-welding-and-machine-shop-inc-474064250 | Q7: =IFERROR(VLOOKUP(J7,Parametros!$A$5:$B$9,2,FALSE()),0) -> 3 | R7: =IFERROR(VLOOKUP(H7,Parametros!$D$5:$E$16,2,FALSE()),1) -> 2 | S7: =IF(OR(N(O7)>=Parametros!$H$9,AND(N(P7)>0,N(P7)<=Parametros!$H$10)),1,0) -> 0 | T7: =Q7+R7+S7 -> 5 | U7: =IF(OR(V7="Inactive",V7="No encontrada"),"Descartada",IF(AND(T7>=Parametros!$H$5,S7=1),"A",IF(T7>=Parametros!$H$6,"B","C"))) -> B | V7: Pendiente
A8: P004 | B8: Hialeah Plumbing Supply Company | C8: Hialeah | E8: Miami-Dade | F8: Distribución suministros de plomería | G8: 42 | H8: 42 Comercio mayorista | I8: Corp | J8: Sin sitio web | K8: Ninguna encontrada | L8: No | M8: Sunbiz: registrada 05/17/1989, Active | Forma legal fuente: Corp (Sunbiz: Florida Profit Corp) | N8: https://search.sunbiz.org/Inquiry/CorporationSearch/ByName | P8: 1989 | Q8: =IFERROR(VLOOKUP(J8,Parametros!$A$5:$B$9,2,FALSE()),0) -> 3 | R8: =IFERROR(VLOOKUP(H8,Parametros!$D$5:$E$16,2,FALSE()),1) -> 2 | S8: =IF(OR(N(O8)>=Parametros!$H$9,AND(N(P8)>0,N(P8)<=Parametros!$H$10)),1,0) -> 1 | T8: =Q8+R8+S8 -> 6 | U8: =IF(OR(V8="Inactive",V8="No encontrada"),"Descartada",IF(AND(T8>=Parametros!$H$5,S8=1),"A",IF(T8>=Parametros!$H$6,"B","C"))) -> A | V8: Active
A9: P005 | B9: Florida Paving & Trucking Inc | C9: Homestead | E9: Miami-Dade | F9: Pavimentación/movimiento de tierra | G9: 23 | H9: 23 Construcción y oficios | I9: Inc | J9: Sin sitio web | K9: Nextdoor | L9: Sí | M9: Est. 1992; solo BBB, D&B, Manta, Yelp, Procore | N9: https://www.bbb.org/us/fl/homestead/profile/paving-contractors/florida-paving-trucking-inc-0633-5003759 | P9: 1992 | Q9: =IFERROR(VLOOKUP(J9,Parametros!$A$5:$B$9,2,FALSE()),0) -> 3 | R9: =IFERROR(VLOOKUP(H9,Parametros!$D$5:$E$16,2,FALSE()),1) -> 3 | S9: =IF(OR(N(O9)>=Parametros!$H$9,AND(N(P9)>0,N(P9)<=Parametros!$H$10)),1,0) -> 1 | T9: =Q9+R9+S9 -> 7 | U9: =IF(OR(V9="Inactive",V9="No encontrada"),"Descartada",IF(AND(T9>=Parametros!$H$5,S9=1),"A",IF(T9>=Parametros!$H$6,"B","C"))) -> A | V9: Pendiente
A10: P006 | B10: Marante Forwarding Co Inc | C10: Hialeah | E10: Miami-Dade | F10: Logística - freight forwarding | G10: 48 | H10: 48-49 Transporte y logística | I10: Inc | J10: Sin sitio web | K10: Ninguna encontrada | L10: No | M10: Est. 1970; licencia OTI revocada 2003: verificar Sunbiz | Forma legal fuente: Inc (posible inactiva) | N10: https://www.manta.com/c/mm2vydb/marante-forwarding-co-inc | P10: 1970 | Q10: =IFERROR(VLOOKUP(J10,Parametros!$A$5:$B$9,2,FALSE()),0) -> 3 | R10: =IFERROR(VLOOKUP(H10,Parametros!$D$5:$E$16,2,FALSE()),1) -> 3 | S10: =IF(OR(N(O10)>=Parametros!$H$9,AND(N(P10)>0,N(P10)<=Parametros!$H$10)),1,0) -> 1 | T10: =Q10+R10+S10 -> 7 | U10: =IF(OR(V10="Inactive",V10="No encontrada"),"Descartada",IF(AND(T10>=Parametros!$H$5,S10=1),"A",IF(T10>=Parametros!$H$6,"B","C"))) -> A | V10: Pendiente | W10: Verificar Sunbiz (posible inactiva)
A11: P007 | B11: Truck Brokerage by National Inc | C11: Medley | E11: Miami-Dade | F11: Transporte de carga (roca/arena) | G11: 48 | H11: 48-49 Transporte y logística | I11: Inc | J11: Sitio obsoleto | K11: Ninguna encontrada | L11: No | M11: Est. 1986, 55 camiones (FMCSA); web http sin HTTPS, páginas .html estáticas | N11: http://www.truckbrokeragebynational.com/ | O11: 55 | P11: 1986 | Q11: =IFERROR(VLOOKUP(J11,Parametros!$A$5:$B$9,2,FALSE()),0) -> 3 | R11: =IFERROR(VLOOKUP(H11,Parametros!$D$5:$E$16,2,FALSE()),1) -> 3 | S11: =IF(OR(N(O11)>=Parametros!$H$9,AND(N(P11)>0,N(P11)<=Parametros!$H$10)),1,0) -> 1 | T11: =Q11+R11+S11 -> 7 | U11: =IF(OR(V11="Inactive",V11="No encontrada"),"Descartada",IF(AND(T11>=Parametros!$H$5,S11=1),"A",IF(T11>=Parametros!$H$6,"B","C"))) -> A | V11: Pendiente
A12: P008 | B12: Construct Group Corp | C12: Hialeah Gardens | E12: Miami-Dade | F12: Contratista civil (FDOT) | G12: 23 | H12: 23 Construcción y oficios | I12: Corp | J12: Sitio obsoleto | K12: Yelp | L12: Sí | M12: Est. 2001, ~100 empleados, 625 proyectos; título web 'HOME | My Site' (plantilla sin personalizar) | N12: https://www.constructgroupcorp.com/ | O12: 100 | P12: 2001 | Q12: =IFERROR(VLOOKUP(J12,Parametros!$A$5:$B$9,2,FALSE()),0) -> 3 | R12: =IFERROR(VLOOKUP(H12,Parametros!$D$5:$E$16,2,FALSE()),1) -> 3 | S12: =IF(OR(N(O12)>=Parametros!$H$9,AND(N(P12)>0,N(P12)<=Parametros!$H$10)),1,0) -> 1 | T12: =Q12+R12+S12 -> 7 | U12: =IF(OR(V12="Inactive",V12="No encontrada"),"Descartada",IF(AND(T12>=Parametros!$H$5,S12=1),"A",IF(T12>=Parametros!$H$6,"B","C"))) -> A | V12: Pendiente
A13: P009 | B13: Professional Plumbing Corp | C13: Hialeah | E13: Miami-Dade | F13: Contratista de plomería comercial | G13: 23 | H13: 23 Construcción y oficios | I13: Corp | J13: Sitio obsoleto | K13: Facebook | L13: Sí | M13: Desde 1973 (W Hotel, Fontainebleau); dos dominios, uno en http | N13: https://www.buildzoom.com/contractor/professional-plumbing-corp | P13: 1973 | Q13: =IFERROR(VLOOKUP(J13,Parametros!$A$5:$B$9,2,FALSE()),0) -> 3 | R13: =IFERROR(VLOOKUP(H13,Parametros!$D$5:$E$16,2,FALSE()),1) -> 3 | S13: =IF(OR(N(O13)>=Parametros!$H$9,AND(N(P13)>0,N(P13)<=Parametros!$H$10)),1,0) -> 1 | T13: =Q13+R13+S13 -> 7 | U13: =IF(OR(V13="Inactive",V13="No encontrada"),"Descartada",IF(AND(T13>=Parametros!$H$5,S13=1),"A",IF(T13>=Parametros!$H$6,"B","C"))) -> A | V13: Pendiente
A14: P010 | B14: AA Florida Pallets Inc | C14: Medley | E14: Miami-Dade | F14: Fabricación/reciclaje de paletas | G14: 32 | H14: 31-33 Manufactura | I14: Inc | J14: Sitio obsoleto | K14: Ninguna encontrada | L14: No | M14: Título web con errata 'Welcom to AA Florida Pallets' | N14: https://www.manta.com/c/mhx9tn8/aa-florida-pallets-inc | Q14: =IFERROR(VLOOKUP(J14,Parametros!$A$5:$B$9,2,FALSE()),0) -> 3 | R14: =IFERROR(VLOOKUP(H14,Parametros!$D$5:$E$16,2,FALSE()),1) -> 2 | S14: =IF(OR(N(O14)>=Parametros!$H$9,AND(N(P14)>0,N(P14)<=Parametros!$H$10)),1,0) -> 0 | T14: =Q14+R14+S14 -> 5 | U14: =IF(OR(V14="Inactive",V14="No encontrada"),"Descartada",IF(AND(T14>=Parametros!$H$5,S14=1),"A",IF(T14>=Parametros!$H$6,"B","C"))) -> B | V14: Pendiente
A15: P011 | B15: High Quality Trucking Inc | C15: Medley | E15: Miami-Dade | F15: Transporte de carga/contenedores | G15: 48 | H15: 48-49 Transporte y logística | I15: Inc | J15: Sitio obsoleto | K15: Ninguna encontrada | L15: No | M15: Est. 2006, 66 camiones; dominio no coincide con la marca | N15: https://www.carriersource.io/carriers/high-quality-trucking-inc | O15: 66 | P15: 2006 | Q15: =IFERROR(VLOOKUP(J15,Parametros!$A$5:$B$9,2,FALSE()),0) -> 3 | R15: =IFERROR(VLOOKUP(H15,Parametros!$D$5:$E$16,2,FALSE()),1) -> 3 | S15: =IF(OR(N(O15)>=Parametros!$H$9,AND(N(P15)>0,N(P15)<=Parametros!$H$10)),1,0) -> 1 | T15: =Q15+R15+S15 -> 7 | U15: =IF(OR(V15="Inactive",V15="No encontrada"),"Descartada",IF(AND(T15>=Parametros!$H$5,S15=1),"A",IF(T15>=Parametros!$H$6,"B","C"))) -> A | V15: Pendiente
A16: P012 | B16: Hialeah Bakery and Foods Inc | C16: Hialeah | E16: Miami-Dade | F16: Panadería | G16: 31 | H16: 31-33 Manufactura | I16: Inc | J16: Tiene web (auditar) | K16: Facebook | L16: Sí | M16: Est. 1996, 24h; contacto con Gmail (señal de baja madurez digital) | N16: https://www.facebook.com/hialeahbakery/ | P16: 1996 | Q16: =IFERROR(VLOOKUP(J16,Parametros!$A$5:$B$9,2,FALSE()),0) -> 1 | R16: =IFERROR(VLOOKUP(H16,Parametros!$D$5:$E$16,2,FALSE()),1) -> 2 | S16: =IF(OR(N(O16)>=Parametros!$H$9,AND(N(P16)>0,N(P16)<=Parametros!$H$10)),1,0) -> 1 | T16: =Q16+R16+S16 -> 4 | U16: =IF(OR(V16="Inactive",V16="No encontrada"),"Descartada",IF(AND(T16>=Parametros!$H$5,S16=1),"A",IF(T16>=Parametros!$H$6,"B","C"))) -> B | V16: Pendiente
A17: P013 | B17: Los Tres Conejitos Bakery | C17: Hialeah | E17: Miami-Dade | F17: Panadería | G17: 31 | H17: 31-33 Manufactura | I17: No verificado | J17: No verificado | K17: Yelp | L17: Sí | M17: Est. 2001, familiar; solo Yelp | N17: https://www.yelp.com/biz/los-tres-conejitos-bakery-hialeah | P17: 2001 | Q17: =IFERROR(VLOOKUP(J17,Parametros!$A$5:$B$9,2,FALSE()),0) -> 1 | R17: =IFERROR(VLOOKUP(H17,Parametros!$D$5:$E$16,2,FALSE()),1) -> 2 | S17: =IF(OR(N(O17)>=Parametros!$H$9,AND(N(P17)>0,N(P17)<=Parametros!$H$10)),1,0) -> 0 | T17: =Q17+R17+S17 -> 3 | U17: =IF(OR(V17="Inactive",V17="No encontrada"),"Descartada",IF(AND(T17>=Parametros!$H$5,S17=1),"A",IF(T17>=Parametros!$H$6,"B","C"))) -> C | V17: Pendiente
A18: P014 | B18: Tango Body Shop | C18: Hialeah | E18: Miami-Dade | F18: Automotriz - carrocería | G18: 81 | H18: 81 Servicios (auto, náutico, reparación) | I18: No verificado | J18: No verificado | K18: Yelp | L18: Sí | M18: 20+ años; solo Yelp | N18: https://www.yelp.com/biz/tango-body-shop-hialeah | Q18: =IFERROR(VLOOKUP(J18,Parametros!$A$5:$B$9,2,FALSE()),0) -> 1 | R18: =IFERROR(VLOOKUP(H18,Parametros!$D$5:$E$16,2,FALSE()),1) -> 2 | S18: =IF(OR(N(O18)>=Parametros!$H$9,AND(N(P18)>0,N(P18)<=Parametros!$H$10)),1,0) -> 0 | T18: =Q18+R18+S18 -> 3 | U18: =IF(OR(V18="Inactive",V18="No encontrada"),"Descartada",IF(AND(T18>=Parametros!$H$5,S18=1),"A",IF(T18>=Parametros!$H$6,"B","C"))) -> C | V18: Pendiente
A19: P015 | B19: Pro Collision Center LLC | C19: Hialeah | E19: Miami-Dade | F19: Automotriz - carrocería | G19: 81 | H19: 81 Servicios (auto, náutico, reparación) | I19: LLC | J19: Presencia desordenada | K19: Yelp; BBB | L19: Sí | M19: Desde 2008, I-Car Gold; dos dominios distintos | N19: https://www.bbb.org/us/fl/hialeah/profile/auto-body-repair-and-painting/procollision-center-llc-0633-90024812 | P19: 2008 | Q19: =IFERROR(VLOOKUP(J19,Parametros!$A$5:$B$9,2,FALSE()),0) -> 2 | R19: =IFERROR(VLOOKUP(H19,Parametros!$D$5:$E$16,2,FALSE()),1) -> 2 | S19: =IF(OR(N(O19)>=Parametros!$H$9,AND(N(P19)>0,N(P19)<=Parametros!$H$10)),1,0) -> 0 | T19: =Q19+R19+S19 -> 4 | U19: =IF(OR(V19="Inactive",V19="No encontrada"),"Descartada",IF(AND(T19>=Parametros!$H$5,S19=1),"A",IF(T19>=Parametros!$H$6,"B","C"))) -> B | V19: Pendiente
A20: P016 | B20: Sari Express Forwarders Inc | C20: Hialeah | E20: Miami-Dade | F20: Logística - freight forwarding | G20: 48 | H20: 48-49 Transporte y logística | I20: Inc | J20: No verificado | K20: Ninguna encontrada | L20: No | M20: Solo Manta | N20: https://www.manta.com/c/mm43fmb/sari-express-forwarders-inc | Q20: =IFERROR(VLOOKUP(J20,Parametros!$A$5:$B$9,2,FALSE()),0) -> 1 | R20: =IFERROR(VLOOKUP(H20,Parametros!$D$5:$E$16,2,FALSE()),1) -> 3 | S20: =IF(OR(N(O20)>=Parametros!$H$9,AND(N(P20)>0,N(P20)<=Parametros!$H$10)),1,0) -> 0 | T20: =Q20+R20+S20 -> 4 | U20: =IF(OR(V20="Inactive",V20="No encontrada"),"Descartada",IF(AND(T20>=Parametros!$H$5,S20=1),"A",IF(T20>=Parametros!$H$6,"B","C"))) -> B | V20: Pendiente
A21: P017 | B21: Global Cargo Connection Inc | C21: Hialeah | E21: Miami-Dade | F21: Logística - consolidación de carga | G21: 48 | H21: 48-49 Transporte y logística | I21: Inc | J21: No verificado | K21: Ninguna encontrada | L21: No | M21: Categoría Freight Forwarding Manta Hialeah | N21: https://www.manta.com/mb_55_B52DB05K_33S/freight_forwarding/hialeah_fl | Q21: =IFERROR(VLOOKUP(J21,Parametros!$A$5:$B$9,2,FALSE()),0) -> 1 | R21: =IFERROR(VLOOKUP(H21,Parametros!$D$5:$E$16,2,FALSE()),1) -> 3 | S21: =IF(OR(N(O21)>=Parametros!$H$9,AND(N(P21)>0,N(P21)<=Parametros!$H$10)),1,0) -> 0 | T21: =Q21+R21+S21 -> 4 | U21: =IF(OR(V21="Inactive",V21="No encontrada"),"Descartada",IF(AND(T21>=Parametros!$H$5,S21=1),"A",IF(T21>=Parametros!$H$6,"B","C"))) -> B | V21: Pendiente
A22: P018 | B22: Marante Distributors Corp | C22: Hialeah | E22: Miami-Dade | F22: Distribución mayorista | G22: 42 | H22: 42 Comercio mayorista | I22: Corp | J22: No verificado | K22: Ninguna encontrada | L22: No | M22: Solo Yahoo Local | N22: https://local.yahoo.com/info-211983306-marante-distributors-corp-hialeah/ | Q22: =IFERROR(VLOOKUP(J22,Parametros!$A$5:$B$9,2,FALSE()),0) -> 1 | R22: =IFERROR(VLOOKUP(H22,Parametros!$D$5:$E$16,2,FALSE()),1) -> 2 | S22: =IF(OR(N(O22)>=Parametros!$H$9,AND(N(P22)>0,N(P22)<=Parametros!$H$10)),1,0) -> 0 | T22: =Q22+R22+S22 -> 3 | U22: =IF(OR(V22="Inactive",V22="No encontrada"),"Descartada",IF(AND(T22>=Parametros!$H$5,S22=1),"A",IF(T22>=Parametros!$H$6,"B","C"))) -> C | V22: Pendiente
A23: P019 | B23: Medina & Son Plumbing Supply Inc | C23: Hialeah | E23: Miami-Dade | F23: Distribución suministros de plomería | G23: 42 | H23: 42 Comercio mayorista | I23: Inc | J23: Tiene web (auditar) | K23: Facebook; Yelp | L23: Sí | M23: Desde 1987, 84+ reseñas | N23: https://www.yelp.com/biz/medina-and-son-plumbing-supply-hialeah | P23: 1987 | Q23: =IFERROR(VLOOKUP(J23,Parametros!$A$5:$B$9,2,FALSE()),0) -> 1 | R23: =IFERROR(VLOOKUP(H23,Parametros!$D$5:$E$16,2,FALSE()),1) -> 2 | S23: =IF(OR(N(O23)>=Parametros!$H$9,AND(N(P23)>0,N(P23)<=Parametros!$H$10)),1,0) -> 1 | T23: =Q23+R23+S23 -> 4 | U23: =IF(OR(V23="Inactive",V23="No encontrada"),"Descartada",IF(AND(T23>=Parametros!$H$5,S23=1),"A",IF(T23>=Parametros!$H$6,"B","C"))) -> B | V23: Pendiente
A24: P020 | B24: Manny's Plumbing Service | C24: Hialeah | E24: Miami-Dade | F24: Plomería | G24: 23 | H24: 23 Construcción y oficios | I24: No verificado | J24: No verificado | K24: Ninguna encontrada | L24: No | M24: Manta: est. 1993 | N24: https://www.manta.com/c/mmf1sbc/manny-s-plumbing-service | Q24: =IFERROR(VLOOKUP(J24,Parametros!$A$5:$B$9,2,FALSE()),0) -> 1 | R24: =IFERROR(VLOOKUP(H24,Parametros!$D$5:$E$16,2,FALSE()),1) -> 3 | S24: =IF(OR(N(O24)>=Parametros!$H$9,AND(N(P24)>0,N(P24)<=Parametros!$H$10)),1,0) -> 0 | T24: =Q24+R24+S24 -> 4 | U24: =IF(OR(V24="Inactive",V24="No encontrada"),"Descartada",IF(AND(T24>=Parametros!$H$5,S24=1),"A",IF(T24>=Parametros!$H$6,"B","C"))) -> B | V24: Pendiente
A25: P021 | B25: All Star Aluminum Windows & Doors Inc | C25: Hialeah | E25: Miami-Dade | F25: Ventanas/puertas de aluminio | G25: 33 | H25: 31-33 Manufactura | I25: Inc | J25: Tiene web (auditar) | K25: Facebook; Yelp; Nextdoor | L25: Sí | M25: Fundada 2003 | N25: https://www.bbb.org/us/fl/hialeah/profile/impact-windows/all-star-aluminum-windows-doors-inc-0633-90034252 | P25: 2003 | Q25: =IFERROR(VLOOKUP(J25,Parametros!$A$5:$B$9,2,FALSE()),0) -> 1 | R25: =IFERROR(VLOOKUP(H25,Parametros!$D$5:$E$16,2,FALSE()),1) -> 2 | S25: =IF(OR(N(O25)>=Parametros!$H$9,AND(N(P25)>0,N(P25)<=Parametros!$H$10)),1,0) -> 0 | T25: =Q25+R25+S25 -> 3 | U25: =IF(OR(V25="Inactive",V25="No encontrada"),"Descartada",IF(AND(T25>=Parametros!$H$5,S25=1),"A",IF(T25>=Parametros!$H$6,"B","C"))) -> C | V25: Pendiente
A26: P022 | B26: Panther & Co Inc | C26: Medley | E26: Miami-Dade | F26: Transporte y almacenaje | G26: 48 | H26: 48-49 Transporte y logística | I26: Inc | J26: Tiene web (auditar) | K26: Facebook; Instagram | L26: Sí | M26: Est. 1989, ~17 empleados, ~$2.7M | N26: https://www.manta.com/c/mtqlxt4/panther-co-inc | O26: 17 | P26: 1989 | Q26: =IFERROR(VLOOKUP(J26,Parametros!$A$5:$B$9,2,FALSE()),0) -> 1 | R26: =IFERROR(VLOOKUP(H26,Parametros!$D$5:$E$16,2,FALSE()),1) -> 3 | S26: =IF(OR(N(O26)>=Parametros!$H$9,AND(N(P26)>0,N(P26)<=Parametros!$H$10)),1,0) -> 1 | T26: =Q26+R26+S26 -> 5 | U26: =IF(OR(V26="Inactive",V26="No encontrada"),"Descartada",IF(AND(T26>=Parametros!$H$5,S26=1),"A",IF(T26>=Parametros!$H$6,"B","C"))) -> B | V26: Pendiente
A27: P023 | B27: Medley Steel and Supply Inc | C27: Medley | E27: Miami-Dade | F27: Distribución de acero | G27: 42 | H27: 42 Comercio mayorista | I27: Inc | J27: Tiene web (auditar) | K27: LinkedIn | L27: Sí | M27: Desde 1978, exporta Caribe/LatAm | N27: https://www.yellowpages.com/medley-fl/medley-steel-and-supply-inc | P27: 1978 | Q27: =IFERROR(VLOOKUP(J27,Parametros!$A$5:$B$9,2,FALSE()),0) -> 1 | R27: =IFERROR(VLOOKUP(H27,Parametros!$D$5:$E$16,2,FALSE()),1) -> 2 | S27: =IF(OR(N(O27)>=Parametros!$H$9,AND(N(P27)>0,N(P27)<=Parametros!$H$10)),1,0) -> 1 | T27: =Q27+R27+S27 -> 4 | U27: =IF(OR(V27="Inactive",V27="No encontrada"),"Descartada",IF(AND(T27>=Parametros!$H$5,S27=1),"A",IF(T27>=Parametros!$H$6,"B","C"))) -> B | V27: Pendiente
A28: P024 | B28: Amigo Pallets Inc | C28: Medley | E28: Miami-Dade | F28: Fabricación/reciclaje de paletas | G28: 32 | H28: 31-33 Manufactura | I28: Inc | J28: Tiene web (auditar) | K28: Facebook; Instagram | L28: Sí | M28: Est. 2010; IG 172 seguidores | N28: https://www.facebook.com/amigopallets/ | P28: 2010 | Q28: =IFERROR(VLOOKUP(J28,Parametros!$A$5:$B$9,2,FALSE()),0) -> 1 | R28: =IFERROR(VLOOKUP(H28,Parametros!$D$5:$E$16,2,FALSE()),1) -> 2 | S28: =IF(OR(N(O28)>=Parametros!$H$9,AND(N(P28)>0,N(P28)<=Parametros!$H$10)),1,0) -> 0 | T28: =Q28+R28+S28 -> 3 | U28: =IF(OR(V28="Inactive",V28="No encontrada"),"Descartada",IF(AND(T28>=Parametros!$H$5,S28=1),"A",IF(T28>=Parametros!$H$6,"B","C"))) -> C | V28: Pendiente
A29: P025 | B29: Medley Machine Shop Inc | C29: Medley | E29: Miami-Dade | F29: Taller mecánico industrial | G29: 33 | H29: 31-33 Manufactura | I29: Inc | J29: Tiene web (auditar) | K29: Ninguna encontrada | L29: No | M29: Fundada 1994; dominio sin confirmar | N29: https://www.dnb.com/business-directory/company-profiles.medley_machine_shop_inc.b0232bd608d5d99948dd3a3504105627.html | P29: 1994 | Q29: =IFERROR(VLOOKUP(J29,Parametros!$A$5:$B$9,2,FALSE()),0) -> 1 | R29: =IFERROR(VLOOKUP(H29,Parametros!$D$5:$E$16,2,FALSE()),1) -> 2 | S29: =IF(OR(N(O29)>=Parametros!$H$9,AND(N(P29)>0,N(P29)<=Parametros!$H$10)),1,0) -> 1 | T29: =Q29+R29+S29 -> 4 | U29: =IF(OR(V29="Inactive",V29="No encontrada"),"Descartada",IF(AND(T29>=Parametros!$H$5,S29=1),"A",IF(T29>=Parametros!$H$6,"B","C"))) -> B | V29: Pendiente
A30: P026 | B30: Pablo's Machine Shop & Welding Corp | C30: Medley | E30: Miami-Dade | F30: Maquinado/soldadura industrial | G30: 81 | H30: 81 Servicios (auto, náutico, reparación) | I30: Corp | J30: Presencia desordenada | K30: Yelp | L30: Sí | M30: Incorporada 2012; dos dominios distintos | N30: https://www.yelp.com/biz/pablos-machine-shop-and-welding-corp-medley | P30: 2012 | Q30: =IFERROR(VLOOKUP(J30,Parametros!$A$5:$B$9,2,FALSE()),0) -> 2 | R30: =IFERROR(VLOOKUP(H30,Parametros!$D$5:$E$16,2,FALSE()),1) -> 2 | S30: =IF(OR(N(O30)>=Parametros!$H$9,AND(N(P30)>0,N(P30)<=Parametros!$H$10)),1,0) -> 0 | T30: =Q30+R30+S30 -> 4 | U30: =IF(OR(V30="Inactive",V30="No encontrada"),"Descartada",IF(AND(T30>=Parametros!$H$5,S30=1),"A",IF(T30>=Parametros!$H$6,"B","C"))) -> B | V30: Pendiente
A31: P027 | B31: Gondia Machine Shop | C31: Medley | E31: Miami-Dade | F31: Taller mecánico industrial | G31: 33 | H31: 31-33 Manufactura | I31: No verificado | J31: No verificado | K31: Ninguna encontrada | L31: No | M31: Solo Manta | N31: https://www.manta.com/c/mm4dqwp/gondia-machine-shop | Q31: =IFERROR(VLOOKUP(J31,Parametros!$A$5:$B$9,2,FALSE()),0) -> 1 | R31: =IFERROR(VLOOKUP(H31,Parametros!$D$5:$E$16,2,FALSE()),1) -> 2 | S31: =IF(OR(N(O31)>=Parametros!$H$9,AND(N(P31)>0,N(P31)<=Parametros!$H$10)),1,0) -> 0 | T31: =Q31+R31+S31 -> 3 | U31: =IF(OR(V31="Inactive",V31="No encontrada"),"Descartada",IF(AND(T31>=Parametros!$H$5,S31=1),"A",IF(T31>=Parametros!$H$6,"B","C"))) -> C | V31: Pendiente
A32: P028 | B32: Super Diesel Truck Repair Inc | C32: Medley | E32: Miami-Dade | F32: Reparación camiones diésel | G32: 81 | H32: 81 Servicios (auto, náutico, reparación) | I32: Inc | J32: Tiene web (auditar) | K32: Yelp; Birdeye | L32: Sí | M32: 3.5 estrellas / 13 reseñas | N32: https://www.manta.com/c/mhcrbf8/super-diesel-truck-repair-inc | Q32: =IFERROR(VLOOKUP(J32,Parametros!$A$5:$B$9,2,FALSE()),0) -> 1 | R32: =IFERROR(VLOOKUP(H32,Parametros!$D$5:$E$16,2,FALSE()),1) -> 2 | S32: =IF(OR(N(O32)>=Parametros!$H$9,AND(N(P32)>0,N(P32)<=Parametros!$H$10)),1,0) -> 0 | T32: =Q32+R32+S32 -> 3 | U32: =IF(OR(V32="Inactive",V32="No encontrada"),"Descartada",IF(AND(T32>=Parametros!$H$5,S32=1),"A",IF(T32>=Parametros!$H$6,"B","C"))) -> C | V32: Pendiente
A33: P029 | B33: LaRosa Diesel Mechanical | C33: Medley | E33: Miami-Dade | F33: Reparación camiones diésel | G33: 81 | H33: 81 Servicios (auto, náutico, reparación) | I33: No verificado | J33: No verificado | K33: Yelp | L33: Sí | M33: Solo Yelp | N33: https://www.yelp.com/biz/larosa-diesel-mechanical-medley | Q33: =IFERROR(VLOOKUP(J33,Parametros!$A$5:$B$9,2,FALSE()),0) -> 1 | R33: =IFERROR(VLOOKUP(H33,Parametros!$D$5:$E$16,2,FALSE()),1) -> 2 | S33: =IF(OR(N(O33)>=Parametros!$H$9,AND(N(P33)>0,N(P33)<=Parametros!$H$10)),1,0) -> 0 | T33: =Q33+R33+S33 -> 3 | U33: =IF(OR(V33="Inactive",V33="No encontrada"),"Descartada",IF(AND(T33>=Parametros!$H$5,S33=1),"A",IF(T33>=Parametros!$H$6,"B","C"))) -> C | V33: Pendiente
A34: P030 | B34: CYMA Truck Repair | C34: Medley | E34: Miami-Dade | F34: Reparación camiones diésel | G34: 81 | H34: 81 Servicios (auto, náutico, reparación) | I34: No verificado | J34: No verificado | K34: Yelp | L34: Sí | M34: Solo Yelp | N34: https://www.yelp.com/biz/cyma-truck-repair-medley | Q34: =IFERROR(VLOOKUP(J34,Parametros!$A$5:$B$9,2,FALSE()),0) -> 1 | R34: =IFERROR(VLOOKUP(H34,Parametros!$D$5:$E$16,2,FALSE()),1) -> 2 | S34: =IF(OR(N(O34)>=Parametros!$H$9,AND(N(P34)>0,N(P34)<=Parametros!$H$10)),1,0) -> 0 | T34: =Q34+R34+S34 -> 3 | U34: =IF(OR(V34="Inactive",V34="No encontrada"),"Descartada",IF(AND(T34>=Parametros!$H$5,S34=1),"A",IF(T34>=Parametros!$H$6,"B","C"))) -> C | V34: Pendiente
A35: P031 | B35: International Cruise Food & Hotel Suppliers Inc | C35: Medley | E35: Miami-Dade | F35: Distribución alimentaria a cruceros | G35: 42 | H35: 42 Comercio mayorista | I35: Inc | J35: Tiene web (auditar) | K35: Nextdoor; Indeed | L35: Sí | M35: Inc. 1998, almacén 200,000 ft² | N35: https://www.manta.com/c/mm21vw1/international-cruise-food-hotel-suppliers-inc | P35: 1998 | Q35: =IFERROR(VLOOKUP(J35,Parametros!$A$5:$B$9,2,FALSE()),0) -> 1 | R35: =IFERROR(VLOOKUP(H35,Parametros!$D$5:$E$16,2,FALSE()),1) -> 2 | S35: =IF(OR(N(O35)>=Parametros!$H$9,AND(N(P35)>0,N(P35)<=Parametros!$H$10)),1,0) -> 1 | T35: =Q35+R35+S35 -> 4 | U35: =IF(OR(V35="Inactive",V35="No encontrada"),"Descartada",IF(AND(T35>=Parametros!$H$5,S35=1),"A",IF(T35>=Parametros!$H$6,"B","C"))) -> B | V35: Pendiente
A36: P032 | B36: Allsteel & Gypsum Products Inc | C36: Medley | E36: Miami-Dade | F36: Distribución materiales de construcción | G36: 42 | H36: 42 Comercio mayorista | I36: Inc | J36: Sitio obsoleto | K36: Ninguna encontrada | L36: No | M36: URL /index.html: sitio estático antiguo (no confirmado) | N36: https://www.allsteelproducts.com/index.html | Q36: =IFERROR(VLOOKUP(J36,Parametros!$A$5:$B$9,2,FALSE()),0) -> 3 | R36: =IFERROR(VLOOKUP(H36,Parametros!$D$5:$E$16,2,FALSE()),1) -> 2 | S36: =IF(OR(N(O36)>=Parametros!$H$9,AND(N(P36)>0,N(P36)<=Parametros!$H$10)),1,0) -> 0 | T36: =Q36+R36+S36 -> 5 | U36: =IF(OR(V36="Inactive",V36="No encontrada"),"Descartada",IF(AND(T36>=Parametros!$H$5,S36=1),"A",IF(T36>=Parametros!$H$6,"B","C"))) -> B | V36: Pendiente
A37: P033 | B37: Structural Prestressed Industries Inc | C37: Medley | E37: Miami-Dade | F37: Prefabricados de concreto | G37: 32 | H37: 31-33 Manufactura | I37: Inc | J37: No verificado | K37: Ninguna encontrada | L37: No | M37: Est. 1996, gran prefabricadora | N37: https://buildingrenewable.com/12-best-precast-concrete-construction-companies-in-florida/ | P37: 1996 | Q37: =IFERROR(VLOOKUP(J37,Parametros!$A$5:$B$9,2,FALSE()),0) -> 1 | R37: =IFERROR(VLOOKUP(H37,Parametros!$D$5:$E$16,2,FALSE()),1) -> 2 | S37: =IF(OR(N(O37)>=Parametros!$H$9,AND(N(P37)>0,N(P37)<=Parametros!$H$10)),1,0) -> 1 | T37: =Q37+R37+S37 -> 4 | U37: =IF(OR(V37="Inactive",V37="No encontrada"),"Descartada",IF(AND(T37>=Parametros!$H$5,S37=1),"A",IF(T37>=Parametros!$H$6,"B","C"))) -> B | V37: Pendiente
A38: P034 | B38: Doral Freight Logistics Inc | C38: Doral | E38: Miami-Dade | F38: Logística - transporte | G38: 48 | H38: 48-49 Transporte y logística | I38: Inc | J38: Tiene web (auditar) | K38: Ninguna encontrada | L38: No | M38: Est. 1999, ~50 empleados, ~$9.4M | N38: https://www.manta.com/c/mm33hkb/doral-freight-logistics-inc | O38: 50 | P38: 1999 | Q38: =IFERROR(VLOOKUP(J38,Parametros!$A$5:$B$9,2,FALSE()),0) -> 1 | R38: =IFERROR(VLOOKUP(H38,Parametros!$D$5:$E$16,2,FALSE()),1) -> 3 | S38: =IF(OR(N(O38)>=Parametros!$H$9,AND(N(P38)>0,N(P38)<=Parametros!$H$10)),1,0) -> 1 | T38: =Q38+R38+S38 -> 5 | U38: =IF(OR(V38="Inactive",V38="No encontrada"),"Descartada",IF(AND(T38>=Parametros!$H$5,S38=1),"A",IF(T38>=Parametros!$H$6,"B","C"))) -> B | V38: Pendiente
A39: P035 | B39: Senaduana Freight Forwarders Inc | C39: Doral | E39: Miami-Dade | F39: Logística - freight forwarding | G39: 48 | H39: 48-49 Transporte y logística | I39: Inc | J39: Tiene web (auditar) | K39: Facebook; LinkedIn; Yelp | L39: Sí | M39: Est. 2004 | N39: https://www.manta.com/c/mmgmgjl/senaduana-freight-forwarders-inc | P39: 2004 | Q39: =IFERROR(VLOOKUP(J39,Parametros!$A$5:$B$9,2,FALSE()),0) -> 1 | R39: =IFERROR(VLOOKUP(H39,Parametros!$D$5:$E$16,2,FALSE()),1) -> 3 | S39: =IF(OR(N(O39)>=Parametros!$H$9,AND(N(P39)>0,N(P39)<=Parametros!$H$10)),1,0) -> 0 | T39: =Q39+R39+S39 -> 4 | U39: =IF(OR(V39="Inactive",V39="No encontrada"),"Descartada",IF(AND(T39>=Parametros!$H$5,S39=1),"A",IF(T39>=Parametros!$H$6,"B","C"))) -> B | V39: Pendiente
A40: P036 | B40: Conavenca Freight Forwarder LLC | C40: Doral | E40: Miami-Dade | F40: Logística - freight forwarding | G40: 48 | H40: 48-49 Transporte y logística | I40: LLC | J40: No verificado | K40: Ninguna encontrada | L40: No | M40: Solo Manta | N40: https://www.manta.com/c/mhks6tw/conavenca-freight-forwarder-llc | Q40: =IFERROR(VLOOKUP(J40,Parametros!$A$5:$B$9,2,FALSE()),0) -> 1 | R40: =IFERROR(VLOOKUP(H40,Parametros!$D$5:$E$16,2,FALSE()),1) -> 3 | S40: =IF(OR(N(O40)>=Parametros!$H$9,AND(N(P40)>0,N(P40)<=Parametros!$H$10)),1,0) -> 0 | T40: =Q40+R40+S40 -> 4 | U40: =IF(OR(V40="Inactive",V40="No encontrada"),"Descartada",IF(AND(T40>=Parametros!$H$5,S40=1),"A",IF(T40>=Parametros!$H$6,"B","C"))) -> B | V40: Pendiente
A41: P037 | B41: TMC Import & Export Co | C41: Doral | E41: Miami-Dade | F41: Import/export (embalaje y equipos) | G41: 42 | H41: 42 Comercio mayorista | I41: LLC | J41: Tiene web (auditar) | K41: Ninguna encontrada | L41: No | M41: Est. 1981, ~11 empleados, ~$2.4M | Forma legal fuente: LLC (según YP) | N41: https://www.manta.com/c/mbg66v7/tmc-import-export-co | O41: 11 | P41: 1981 | Q41: =IFERROR(VLOOKUP(J41,Parametros!$A$5:$B$9,2,FALSE()),0) -> 1 | R41: =IFERROR(VLOOKUP(H41,Parametros!$D$5:$E$16,2,FALSE()),1) -> 2 | S41: =IF(OR(N(O41)>=Parametros!$H$9,AND(N(P41)>0,N(P41)<=Parametros!$H$10)),1,0) -> 1 | T41: =Q41+R41+S41 -> 4 | U41: =IF(OR(V41="Inactive",V41="No encontrada"),"Descartada",IF(AND(T41>=Parametros!$H$5,S41=1),"A",IF(T41>=Parametros!$H$6,"B","C"))) -> B | V41: Pendiente
...

Sheet TD_Area_Web
A1: Tabla dinámica: prospectos por condado, municipio y estado web
A2: Origen: hoja Prospectos. Clic derecho > Actualizar tras editar datos. Filtros en la fila superior de la tabla.
A4: Filter
A6: Count - Empresa | C6: Estado web
A7: Condado | B7: Municipio | C7: No verificado | D7: Presencia desordenada | E7: Sin sitio web | F7: Sitio obsoleto | G7: Tiene web (auditar) | H7: Total Result
A8: Broward | B8: Davie | C8: 2 | D8: 1 | E8: 2 | H8: 5
B9: Fort Lauderdale | C9: 1 | E9: 5 | F9: 1 | H9: 7
B10: Miramar | C10: 4 | H10: 4
B11: Pompano Beach | C11: 7 | E11: 2 | F11: 1 | H11: 10
B12: Sunrise | C12: 5 | H12: 5
A13: Miami-Dade | B13: Doral | C13: 5 | G13: 3 | H13: 8
B14: Hialeah | C14: 6 | D14: 1 | E14: 3 | F14: 1 | G14: 3 | H14: 14
B15: Hialeah Gardens | F15: 1 | H15: 1
B16: Homestead | C16: 5 | E16: 1 | G16: 2 | H16: 8
B17: Kendall | C17: 2 | G17: 1 | H17: 3
B18: Medley | C18: 4 | D18: 1 | E18: 2 | F18: 4 | G18: 6 | H18: 17
B19: Miami (ciudad) | C19: 2 | G19: 4 | H19: 6
B20: Miami Beach | C20: 1 | H20: 1
B21: Miami Shores | C21: 1 | H21: 1
B22: North Miami | C22: 4 | H22: 4
B23: North Miami Beach | C23: 1 | H23: 1
A24: Total Result | C24: 50 | D24: 3 | E24: 15 | F24: 8 | G24: 19 | H24: 95

Sheet TD_Industria_Web
A1: Tabla dinámica: industria × estado web (filtro: condado)
A2: Origen: hoja Prospectos. Clic derecho > Actualizar tras editar datos. Filtros en la fila superior de la tabla.
A4: Filter
A5: Condado | B5: - all -
A7: Count - Empresa | B7: Estado web
A8: Industria (NAICS) | B8: No verificado | C8: Presencia desordenada | D8: Sin sitio web | E8: Sitio obsoleto | F8: Tiene web (auditar) | G8: Total Result
A9: 11 Agricultura/viveros | B9: 5 | F9: 1 | G9: 6
A10: 23 Construcción y oficios | B10: 11 | D10: 3 | E10: 2 | F10: 1 | G10: 17
A11: 31-33 Manufactura | B11: 3 | D11: 3 | E11: 1 | F11: 4 | G11: 11
A12: 42 Comercio mayorista | B12: 4 | D12: 1 | E12: 1 | F12: 7 | G12: 13
A13: 48-49 Transporte y logística | B13: 7 | D13: 1 | E13: 2 | F13: 3 | G13: 13
A14: 53 Inmobiliario/admin. propiedades | B14: 5 | G14: 5
A15: 62 Salud | B15: 4 | G15: 4
A16: 72 Restaurantes/hotelería | B16: 1 | F16: 1 | G16: 2
A17: 81 Servicios (auto, náutico, reparación) | B17: 10 | C17: 3 | D17: 7 | E17: 2 | F17: 2 | G17: 24
A18: Total Result | B18: 50 | C18: 3 | D18: 15 | E18: 8 | F18: 19 | G18: 95

Sheet TD_Legal_Prioridad
A1: Tabla dinámica: forma legal × prioridad (filtro: condado)
A2: Origen: hoja Prospectos. Clic derecho > Actualizar tras editar datos. Filtros en la fila superior de la tabla.
A4: Filter
A5: Condado | B5: - all -
A7: Count - Empresa | B7: Prioridad
A8: Forma legal | B8: A | C8: B | D8: C | E8: Descartada | F8: Total Result
A9: Corp | B9: 3 | C9: 2 | D9: 2 | F9: 7
A10: Inc | B10: 6 | C10: 31 | D10: 9 | E10: 1 | F10: 47
A11: LLC | B11: 1 | C11: 7 | D11: 4 | F11: 12
A12: No verificado | B12: 3 | C12: 10 | D12: 16 | F12: 29
A13: Total Result | B13: 13 | C13: 50 | D13: 31 | E13: 1 | F13: 95

Sheet TD_Redes
A1: Tabla dinámica: presencia en redes sociales × condado (filtro: industria)
A2: Origen: hoja Prospectos. Clic derecho > Actualizar tras editar datos. Filtros en la fila superior de la tabla.
A4: Filter
A5: Industria (NAICS) | B5: - all -
A7: Count - Empresa | B7: Condado
A8: Tiene redes | B8: Broward | C8: Miami-Dade | D8: Total Result
A9: No | B9: 6 | C9: 29 | D9: 35
A10: No verificado | B10: 19 | C10: 6 | D10: 25
A11: Sí | B11: 6 | C11: 29 | D11: 35
A12: Total Result | B12: 31 | C12: 64 | D12: 95

Sheet Parametros
A1: Parámetros del puntaje
A2: Azul = supuestos editables. El puntaje de Prospectos se recalcula al cambiarlos.
A4: Estado web | B4: Peso | D4: Industria (NAICS) | E4: Peso | G4: Prioridad | H4: Puntaje mínimo
A5: Sin sitio web | B5: 3 | D5: 23 Construcción y oficios | E5: 3 | G5: A | H5: 6 | I5: CPL $76–228: alto valor por cliente
A6: Sitio obsoleto | B6: 3 | D6: 48-49 Transporte y logística | E6: 3 | G6: B | H6: 4 | I6: B2B, tamaño medio, baja madurez digital
A7: Presencia desordenada | B7: 2 | D7: 62 Salud | E7: 3 | G7: C | H7: < B | I7: CPC $5–10, alta intención local
A8: No verificado | B8: 1 | D8: 54 Servicios profesionales | E8: 3 | I8: CPC legal $9.87+, ticket alto
A9: Tiene web (auditar) | B9: 1 | D9: 42 Comercio mayorista | E9: 2 | G9: Empleados mín. | H9: 10 | I9: B2B CPL $103; decisión lenta
D10: 31-33 Manufactura | E10: 2 | G10: Fundada hasta | H10: 2000 | I10: B2B, catálogo/cotizador
D11: 53 Inmobiliario/admin. propiedades | E11: 2 | I11: CPL $100
D12: 81 Servicios (auto, náutico, reparación) | E12: 2 | I12: Náutico FTL: ticket alto; auto CPL $28
D13: 72 Restaurantes/hotelería | E13: 1 | I13: Ticket bajo, CPC $2
D14: 11 Agricultura/viveros | E14: 1 | I14: Mayorista, baja demanda de search
D15: Sin clasificar | E15: 1
A18: Puntaje = Peso web + Peso sector + Señal tamaño (1 si ≥10 empleados/camiones o fundada ≤2000). Máx. 7. Prioridad A exige además Señal tamaño = 1 (empresa mediana/establecida). Inactive en Sunbiz = Descartada.
A19: Pesos de sector derivados de benchmarks Google Ads (hoja Google_Ads) y ticket de servicio esperado. Criterio propio, ajustable.

Sheet Oportunidad_Industria
A1: Matriz de oportunidad por industria
A2: Conteos vivos desde Prospectos. Ticket y CPL = supuestos editables (azul) con fuente en Google_Ads.
A4: Industria (NAICS) | B4: Prospectos | C4: Sin web | D4: Sitio obsoleto | E4: Desordenada | F4: Brecha (sin web+obsoleto+desordenada) | G4: % brecha | H4: Prioridad A | I4: Ticket web (USD) | J4: Retainer mensual (USD) | K4: Valor potencial año 1 (USD) | L4: CPL ref. Google Ads (USD)
A5: 23 Construcción y oficios | B5: =COUNTIF(Prospectos!$H$5:$H$99,A5) -> 17 | C5: =COUNTIFS(Prospectos!$H$5:$H$99,A5,Prospectos!$J$5:$J$99,"Sin sitio web") -> 3 | D5: =COUNTIFS(Prospectos!$H$5:$H$99,A5,Prospectos!$J$5:$J$99,"Sitio obsoleto") -> 2 | E5: =COUNTIFS(Prospectos!$H$5:$H$99,A5,Prospectos!$J$5:$J$99,"Presencia desordenada") -> 0 | F5: =C5+D5+E5 -> 5 | G5: =IF(B5=0,0,F5/B5) -> 0.29411765 | H5: =COUNTIFS(Prospectos!$H$5:$H$99,A5,Prospectos!$U$5:$U$99,"A") -> 3 | I5: 4500 | J5: 1500 | K5: =F5*(I5+J5*12) -> 112500 | L5: 76.4
A6: 48-49 Transporte y logística | B6: =COUNTIF(Prospectos!$H$5:$H$99,A6) -> 13 | C6: =COUNTIFS(Prospectos!$H$5:$H$99,A6,Prospectos!$J$5:$J$99,"Sin sitio web") -> 1 | D6: =COUNTIFS(Prospectos!$H$5:$H$99,A6,Prospectos!$J$5:$J$99,"Sitio obsoleto") -> 2 | E6: =COUNTIFS(Prospectos!$H$5:$H$99,A6,Prospectos!$J$5:$J$99,"Presencia desordenada") -> 0 | F6: =C6+D6+E6 -> 3 | G6: =IF(B6=0,0,F6/B6) -> 0.23076923 | H6: =COUNTIFS(Prospectos!$H$5:$H$99,A6,Prospectos!$U$5:$U$99,"A") -> 3 | I6: 5000 | J6: 1500 | K6: =F6*(I6+J6*12) -> 69000 | L6: 103.54
A7: 62 Salud | B7: =COUNTIF(Prospectos!$H$5:$H$99,A7) -> 4 | C7: =COUNTIFS(Prospectos!$H$5:$H$99,A7,Prospectos!$J$5:$J$99,"Sin sitio web") -> 0 | D7: =COUNTIFS(Prospectos!$H$5:$H$99,A7,Prospectos!$J$5:$J$99,"Sitio obsoleto") -> 0 | E7: =COUNTIFS(Prospectos!$H$5:$H$99,A7,Prospectos!$J$5:$J$99,"Presencia desordenada") -> 0 | F7: =C7+D7+E7 -> 0 | G7: =IF(B7=0,0,F7/B7) -> 0 | H7: =COUNTIFS(Prospectos!$H$5:$H$99,A7,Prospectos!$U$5:$U$99,"A") -> 0 | I7: 4500 | J7: 1800 | K7: =F7*(I7+J7*12) -> 0 | L7: 56.83
A8: 54 Servicios profesionales | B8: =COUNTIF(Prospectos!$H$5:$H$99,A8) -> 0 | C8: =COUNTIFS(Prospectos!$H$5:$H$99,A8,Prospectos!$J$5:$J$99,"Sin sitio web") -> 0 | D8: =COUNTIFS(Prospectos!$H$5:$H$99,A8,Prospectos!$J$5:$J$99,"Sitio obsoleto") -> 0 | E8: =COUNTIFS(Prospectos!$H$5:$H$99,A8,Prospectos!$J$5:$J$99,"Presencia desordenada") -> 0 | F8: =C8+D8+E8 -> 0 | G8: =IF(B8=0,0,F8/B8) -> 0 | H8: =COUNTIFS(Prospectos!$H$5:$H$99,A8,Prospectos!$U$5:$U$99,"A") -> 0 | I8: 6000 | J8: 2000 | K8: =F8*(I8+J8*12) -> 0 | L8: 131.63
A9: 42 Comercio mayorista | B9: =COUNTIF(Prospectos!$H$5:$H$99,A9) -> 13 | C9: =COUNTIFS(Prospectos!$H$5:$H$99,A9,Prospectos!$J$5:$J$99,"Sin sitio web") -> 1 | D9: =COUNTIFS(Prospectos!$H$5:$H$99,A9,Prospectos!$J$5:$J$99,"Sitio obsoleto") -> 1 | E9: =COUNTIFS(Prospectos!$H$5:$H$99,A9,Prospectos!$J$5:$J$99,"Presencia desordenada") -> 0 | F9: =C9+D9+E9 -> 2 | G9: =IF(B9=0,0,F9/B9) -> 0.15384615 | H9: =COUNTIFS(Prospectos!$H$5:$H$99,A9,Prospectos!$U$5:$U$99,"A") -> 1 | I9: 4000 | J9: 1200 | K9: =F9*(I9+J9*12) -> 36800 | L9: 103.54
A10: 31-33 Manufactura | B10: =COUNTIF(Prospectos!$H$5:$H$99,A10) -> 11 | C10: =COUNTIFS(Prospectos!$H$5:$H$99,A10,Prospectos!$J$5:$J$99,"Sin sitio web") -> 3 | D10: =COUNTIFS(Prospectos!$H$5:$H$99,A10,Prospectos!$J$5:$J$99,"Sitio obsoleto") -> 1 | E10: =COUNTIFS(Prospectos!$H$5:$H$99,A10,Prospectos!$J$5:$J$99,"Presencia desordenada") -> 0 | F10: =C10+D10+E10 -> 4 | G10: =IF(B10=0,0,F10/B10) -> 0.36363636 | H10: =COUNTIFS(Prospectos!$H$5:$H$99,A10,Prospectos!$U$5:$U$99,"A") -> 2 | I10: 4000 | J10: 1200 | K10: =F10*(I10+J10*12) -> 73600 | L10: 103.54
A11: 53 Inmobiliario/admin. propiedades | B11: =COUNTIF(Prospectos!$H$5:$H$99,A11) -> 5 | C11: =COUNTIFS(Prospectos!$H$5:$H$99,A11,Prospectos!$J$5:$J$99,"Sin sitio web") -> 0 | D11: =COUNTIFS(Prospectos!$H$5:$H$99,A11,Prospectos!$J$5:$J$99,"Sitio obsoleto") -> 0 | E11: =COUNTIFS(Prospectos!$H$5:$H$99,A11,Prospectos!$J$5:$J$99,"Presencia desordenada") -> 0 | F11: =C11+D11+E11 -> 0 | G11: =IF(B11=0,0,F11/B11) -> 0 | H11: =COUNTIFS(Prospectos!$H$5:$H$99,A11,Prospectos!$U$5:$U$99,"A") -> 0 | I11: 3500 | J11: 1200 | K11: =F11*(I11+J11*12) -> 0 | L11: 100.48
A12: 81 Servicios (auto, náutico, reparación) | B12: =COUNTIF(Prospectos!$H$5:$H$99,A12) -> 24 | C12: =COUNTIFS(Prospectos!$H$5:$H$99,A12,Prospectos!$J$5:$J$99,"Sin sitio web") -> 7 | D12: =COUNTIFS(Prospectos!$H$5:$H$99,A12,Prospectos!$J$5:$J$99,"Sitio obsoleto") -> 2 | E12: =COUNTIFS(Prospectos!$H$5:$H$99,A12,Prospectos!$J$5:$J$99,"Presencia desordenada") -> 3 | F12: =C12+D12+E12 -> 12 | G12: =IF(B12=0,0,F12/B12) -> 0.5 | H12: =COUNTIFS(Prospectos!$H$5:$H$99,A12,Prospectos!$U$5:$U$99,"A") -> 4 | I12: 3000 | J12: 1000 | K12: =F12*(I12+J12*12) -> 180000 | L12: 28.5
A13: 72 Restaurantes/hotelería | B13: =COUNTIF(Prospectos!$H$5:$H$99,A13) -> 2 | C13: =COUNTIFS(Prospectos!$H$5:$H$99,A13,Prospectos!$J$5:$J$99,"Sin sitio web") -> 0 | D13: =COUNTIFS(Prospectos!$H$5:$H$99,A13,Prospectos!$J$5:$J$99,"Sitio obsoleto") -> 0 | E13: =COUNTIFS(Prospectos!$H$5:$H$99,A13,Prospectos!$J$5:$J$99,"Presencia desordenada") -> 0 | F13: =C13+D13+E13 -> 0 | G13: =IF(B13=0,0,F13/B13) -> 0 | H13: =COUNTIFS(Prospectos!$H$5:$H$99,A13,Prospectos!$U$5:$U$99,"A") -> 0 | I13: 2500 | J13: 800 | K13: =F13*(I13+J13*12) -> 0 | L13: 30.27
A14: 11 Agricultura/viveros | B14: =COUNTIF(Prospectos!$H$5:$H$99,A14) -> 6 | C14: =COUNTIFS(Prospectos!$H$5:$H$99,A14,Prospectos!$J$5:$J$99,"Sin sitio web") -> 0 | D14: =COUNTIFS(Prospectos!$H$5:$H$99,A14,Prospectos!$J$5:$J$99,"Sitio obsoleto") -> 0 | E14: =COUNTIFS(Prospectos!$H$5:$H$99,A14,Prospectos!$J$5:$J$99,"Presencia desordenada") -> 0 | F14: =C14+D14+E14 -> 0 | G14: =IF(B14=0,0,F14/B14) -> 0 | H14: =COUNTIFS(Prospectos!$H$5:$H$99,A14,Prospectos!$U$5:$U$99,"A") -> 0 | I14: 3000 | J14: 800 | K14: =F14*(I14+J14*12) -> 0 | L14: 70.11
A15: Total | B15: =SUM(B5:B14) -> 95 | C15: =SUM(C5:C14) -> 15 | D15: =SUM(D5:D14) -> 8 | E15: =SUM(E5:E14) -> 3 | F15: =SUM(F5:F14) -> 26 | G15: =IF(B15=0,0,F15/B15) -> 0.27368421 | H15: =SUM(H5:H14) -> 13 | K15: =SUM(K5:K14) -> 471900
A17: Valor potencial año 1 = empresas con brecha × (ticket web + retainer × 12). Asume 100% de cierre: aplicar tasa de conversión real (típico B2B frío 2–5%).
A18: Tickets: rangos Miami web pyme $2,500–15,000; SEO local $750–3,000/mes; redes $1,000–3,000/mes (ver Google_Ads). Valores de la tabla = punto medio conservador.

Sheet Macro_Areas
A1: Contexto económico por área
A2: Census QuickFacts / ABS 2022, municipios y DataUSA. 'Estimado' = no verificado en fuente primaria.
A4: Área | B4: Condado | C4: Población | D4: Año | E4: Firmas empleadoras (ABS 2022) | F4: Carácter económico | G4: NAICS clave | H4: Verificación | I4: Fuente
A5: Miami (ciudad) | B5: Miami-Dade | C5: 455924 | D5: 2023 | E5: 17986 | F5: Finanzas, servicios profesionales, turismo, hub LatAm | G5: 54, 52, 72, 42 | H5: Sí | I5: https://www.census.gov/quickfacts/fact/table/miamicityflorida/PST045224
A6: Hialeah | B6: Miami-Dade | C6: 226000 | D6: 2024 | F6: Manufactura ligera, salud, construcción, transporte | G6: 31-33, 62, 23, 48-49 | H6: Estimado | I6: https://datausa.io/profile/geo/hialeah-fl/
A7: Doral | B7: Miami-Dade | C7: 83625 | D7: 2024 | E7: 5300 | F7: Logística, comercio exterior, freight forwarders (junto a MIA) | G7: 48-49, 42, 54, 44-45 | H7: Estimado | I7: https://www.census.gov/quickfacts/fact/table/doralcityflorida/PST045225
A8: Medley | B8: Miami-Dade | C8: 1056 | D8: 2020 | E8: 1800 | F8: Industrial pura: cemento, canteras, +350 almacenes; población diurna +60k | G8: 31-33, 42, 48-49, 23 | H8: Sí (municipio) | I8: https://www.townofmedley.com/about-us
A9: Miami Beach | B9: Miami-Dade | C9: 82031 | D9: 2024 | E9: 4174 | F9: Hotelería, restaurantes, vida nocturna, real estate | G9: 72, 53, 71, 81 | H9: Sí | I9: https://census.gov/quickfacts/fact/table/miamibeachcityflorida/POP060210
A10: Coral Gables | B10: Miami-Dade | C10: 48353 | D10: 2023 | E10: 5120 | F10: Sedes multinacionales LatAm, legal, profesional | G10: 54, 52, 55, 62 | H10: Sí | I10: https://www.census.gov/quickfacts/fact/table/coralgablescityflorida/PST045224
A11: Kendall | B11: Miami-Dade | C11: 80241 | D11: 2020 | F11: Retail (Dadeland), salud (Baptist), servicios | G11: 44-45, 62, 81, 61 | H11: Sí (población) | I11: https://en.wikipedia.org/wiki/Kendall,_Florida
A12: Miami Gardens | B12: Miami-Dade | C12: 111000 | D12: 2024 | F12: Residencial, retail, Hard Rock Stadium | G12: 44-45, 71, 81 | H12: Estimado | I12: https://www.census.gov/quickfacts/fact/table/miamigardenscityflorida/POP060210
A13: Homestead | B13: Miami-Dade | C13: 82807 | D13: 2024 | E13: 1212 | F13: Agricultura/viveros, base aérea, puerta a Cayos | G13: 11, 44-45, 72, 23 | H13: Sí | I13: https://census.gov/quickfacts/fact/table/homesteadcityflorida/PST120223
A14: Fort Lauderdale | B14: Broward | C14: 184255 | D14: 2023 | E14: 10690 | F14: Industria náutica (111k empleos Broward), turismo, finanzas | G14: 48-49, 72, 52, 81 | H14: Sí | I14: https://www.census.gov/quickfacts/fact/table/fortlauderdalecityflorida/PST045225
A15: Hollywood | B15: Broward | C15: 152650 | D15: 2022 | E15: 5007 | F15: Turismo de playa, retail, servicios | G15: 72, 44-45, 81 | H15: Sí | I15: https://www.census.gov/quickfacts/fact/table/hollywoodcityflorida/PST045222
A16: Pembroke Pines | B16: Broward | C16: 179326 | D16: 2024 | E16: 4128 | F16: Residencial, retail, salud | G16: 44-45, 62, 81 | H16: Sí | I16: https://www.census.gov/quickfacts/fact/table/pembrokepinescityflorida/SBO010222
A17: Sunrise | B17: Broward | C17: 100128 | D17: 2024 | E17: 2706 | F17: Retail (Sawgrass Mills), oficinas corporativas | G17: 44-45, 55, 54 | H17: Sí | I17: https://www.census.gov/quickfacts/fact/table/sunrisecityflorida/PST045222
A18: Plantation | B18: Broward | C18: 96000 | D18: 2024 | F18: Oficinas, salud, retail | G18: 54, 62, 44-45 | H18: Estimado | I18: https://www.census.gov/quickfacts/fact/table/plantationcityflorida/PST045225
A20: Condados
A21: Condado | B21: Población | C21: Establecimientos (CBP) | D21: Año | E21: Est. 20–99 empl. | F21: Est. 100–499 empl. | G21: Mid-market (20–499) | H21: % mid-market | I21: Fuente
A22: Miami-Dade | B22: 2738356 | C22: 98394 | D22: 2023 | E22: 12000 | F22: 2200 | G22: =E22+F22 -> 14200 | H22: =IF(C22=0,0,G22/C22) -> 0.14431774 | I22: https://www.miamidadematters.org/indicators/index/view?indicatorId=6371&localeId=414
A23: Broward | B23: 2000000 | C23: 67274 | D23: 2022 | E23: 8200 | F23: 1500 | G23: =E23+F23 -> 9700 | H23: =IF(C23=0,0,G23/C23) -> 0.14418646 | I23: https://www.census.gov/quickfacts/fact/table/browardcountyflorida/PST045224
A24: Est. 20–99 y 100–499 = ESTIMADO (proporciones nacionales CBP ≈12% y ≈2.2%). Verificar en data.census.gov tabla CB2300CBP, FIPS 12086 y 12011.

Sheet Adopcion_Digital
A1: Adopción digital y formación de empresas
A2: Encuestas nacionales (no hay datos específicos de Florida) + estadísticas oficiales.
A4: Indicador | B4: Valor | C4: Año | D4: Fuente | E4: URL
A5: Pequeñas empresas EE.UU. sin sitio web | B5: 17% | C5: 2025 | D5: Clutch | E5: https://clutch.co/press-releases/smb-websites-2025
A6: Sin sitio web (Top Design Firms) | B6: 27% | C6: 2022 | D6: Top Design Firms | E6: https://www.prnewswire.com/news-releases/27-of-small-businesses-still-dont-have-a-website-in-2022-301542302.html
A7: De las que no tienen web: creen que no la necesitan | B7: 34% | C7: 2025 | D7: Clutch | E7: https://clutch.co/press-releases/smb-websites-2025
A8: Invierten en publicidad de búsqueda (año en curso) | B8: 45% | C8: 2026 | D8: LocaliQ | E8: https://localiq.com/blog/small-business-marketing-trends-report-2026/
A9: Invierten en search con presupuesto < $1k/mes | B9: 30% | C9: 2026 | D9: LocaliQ | E9: https://localiq.com/blog/small-business-marketing-trends-report-2026/
A10: Pymes que usan IA generativa | B10: 58% | C10: 2025 | D10: US Chamber | E10: https://www.uschamber.com/technology/artificial-intelligence/u-s-chambers-latest-empowering-small-business-report-shows-majority-of-businesses-in-all-50-states-are-embracing-ai
A11: Solicitudes de negocio Florida (Census BFS) | B11: ~634,000 | C11: 2024 | D11: Census BFS / Business Observer | E11: https://www.businessobserverfl.com/news/2025/may/19/florida-new-business-formations/
A12: Solicitudes por 10k hab. Miami-Dade (6.º EE.UU.) | B12: 532 | C12: 2024 | D12: Census BFS / Business Observer | E12: https://www.businessobserverfl.com/news/2025/may/19/florida-new-business-formations/
A13: Solicitudes por 10k hab. Broward (11.º EE.UU.) | B13: 418 | C13: 2024 | D13: Census BFS / Business Observer | E13: https://www.businessobserverfl.com/news/2025/may/19/florida-new-business-formations/
A14: Pequeñas empresas en Florida (99.8% del total) | B14: 3.5 M | C14: 2025 | D14: SBA Office of Advocacy | E14: https://advocacy.sba.gov/wp-content/uploads/2025/06/Florida_2025-State-Profile.pdf
A15: Entidades registradas en Sunbiz | B15: +3.5 M | C15: 2026 | D15: Florida Division of Corporations | E15: https://dos.fl.gov/sunbiz/
... A18: Demandas digitales ADA Florida (fed.+estatal) | B18: 950 (24% EE.UU.) | C18: 2025 | D18: UsableNet | E18: https://blog.usablenet.com/ada-web-lawsuit-trends-2026

Sheet Google_Ads
A1: Google Ads: benchmarks y precios de servicios
A2: WordStream/LocaliQ = muestras grandes. Keywords Miami = herramientas de agencia (orientativo). Confirmar con Keyword Planner.
A4: Industria / keyword | B4: NAICS | C4: CPC (USD) | D4: CPL (USD) | E4: Nota | F4: Fuente
A5: Promedio todas las industrias | C5: 5.26 | D5: 70.11 | E5: WordStream 2025 (16k+ campañas) | F5: https://www.wordstream.com/blog/2025-google-ads-benchmarks
A6: Legal / abogados | B6: 54 | C6: 9.87 | D6: 131.63 | E6: CPC 2026; CPL más alto | F6: https://www.wordstream.com/blog/2026-google-ads-benchmarks
A7: Dental | B7: 62 | C7: 8 | E7: CPC 2026; conv. 9.08% | F7: https://www.wordstream.com/blog/2026-google-ads-benchmarks
A8: Médicos y cirujanos | B8: 62 | C8: 5 | D8: 56.83 | E8: WordStream 2025 | F8: https://www.wordstream.com/blog/2025-google-ads-benchmarks
A9: Techos (roofing) | B9: 23 | C9: 10.7 | D9: 228.15 | E9: LocaliQ home services 2025 | F9: https://localiq.com/blog/home-services-search-advertising-benchmarks/
A10: Plomería | B10: 23 | D10: 76.4 | E10: LocaliQ home services 2025 | F10: https://localiq.com/blog/home-services-search-advertising-benchmarks/
A11: HVAC | B11: 23 | D11: 84.92 | E11: LocaliQ home services 2025 | F11: https://localiq.com/blog/home-services-search-advertising-benchmarks/
A12: Construcción | B12: 23 | C12: 5.31 | E12: LocaliQ home services 2025 | F12: https://localiq.com/blog/home-services-search-advertising-benchmarks/
A13: Automotriz (reparación) | B13: 81 | D13: 28.5 | E13: WordStream 2025 | F13: https://www.wordstream.com/blog/2025-google-ads-benchmarks
A14: Restaurantes | B14: 72 | C14: 2.05 | D14: 30.27 | E14: WordStream 2025 | F14: https://www.wordstream.com/blog/2025-google-ads-benchmarks
A15: Business services (B2B) | B15: 42 | D15: 103.54 | E15: WordStream 2025 | F15: https://www.wordstream.com/blog/2025-google-ads-benchmarks
A16: Real estate | B16: 53 | D16: 100.48 | E16: WordStream 2025 | F16: https://www.wordstream.com/blog/2025-google-ads-benchmarks
A17: 'dentist miami' | B17: 62 | C17: 9.81 | D17: 105 | E17: Herramienta de agencia; orientativo | F17: https://ppcchief.com/google-ads-cost/dental/miami
A18: Accidentes / PI Miami (inglés) | B18: 54 | C18: 70 | D18: 300 | E18: Rango CPC $70–250+; CPL $300–1,000 | F18: https://custom.legal/practice-areas/personal-injury-law-firm-marketing/cost-per-click-benchmarks-for-personal-injury/
A19: 'abogado de accidentes' FL (español) | B19: 54 | C19: 45 | E19: CPC $45–85; 30–60% más barato que inglés | F19: https://www.greatmarketing.ai/blog/spanish-speaking-personal-injury-lawyer-marketing
A21: Precios de mercado de servicios digitales (Miami)
A22: Servicio | B22: Mínimo (USD) | C22: Máximo (USD) | D22: Punto medio | E22: Unidad | F22: Fuente
A23: Diseño web pyme (Miami) | B23: 2500 | C23: 15000 | D23: =AVERAGE(B23:C23) -> 8750 | E23: proyecto | F23: https://tamer.marketing/blog/web-design-cost-miami/
A24: Diseño web freelance / precio fijo | B24: 500 | C24: 2000 | D24: =AVERAGE(B24:C24) -> 1250 | E24: proyecto | F24: https://startupstarz.com/how-much-does-a-website-cost-for-a-small-business-in-miami-2026-pricing-guide/
A25: SEO local pyme (Miami) | B25: 750 | C25: 3000 | D25: =AVERAGE(B25:C25) -> 1875 | E25: mes | F25: https://tamer.marketing/blog/seo-cost-miami/
A26: Gestión redes sociales pyme (Miami) | B26: 1000 | C26: 3000 | D26: =AVERAGE(B26:C26) -> 2000 | E26: mes | F26: https://onceonceagency.com/social-media-management-cost-miami/
A27: Gestión Google Ads (fee) | B27: 500 | C27: 2500 | D27: =AVERAGE(B27:C27) -> 1500 | E27: mes (10–20% del gasto, mín. ~$500) | F27: https://www.2pointagency.com/glossary/pricing-for-ppc-management-services-in-miami/
A28: Presupuesto Google Ads pyme local | B28: 1000 | C28: 2500 | D28: =AVERAGE(B28:C28) -> 1750 | E28: mes (inversión del cliente) | F28: https://www.americaneagle.com/insights/blog/post/how-much-does-it-cost-to-advertise-on-google-ads-in-2025

Sheet Legal_Cumplimiento
A1: Legalidad de empresas y cumplimiento comercial
A2: Florida Division of Corporations (Sunbiz), DBPR, BTR condado/ciudad, FTSA, TCPA, CAN-SPAM, ADA. No es asesoría legal.
A4: Tema | B4: Regla / dato | C4: Implicación comercial | D4: Fuente oficial
A5: Sunbiz – tipos de entidad | B5: Florida Profit Corp, Not For Profit, LLC, LP/LLLP, Foreign, Fictitious Name (DBA, $50, 5 años, F.S. 865.09) | C5: 'Inc/Corp/LLC' en el nombre no confirma estatus: validar siempre en Sunbiz | D5: https://dos.fl.gov/sunbiz/start-business/efile/fl-fictitious-name-registration/
A6: Sunbiz – estados | B6: Active / Inactive (Admin Dissolution for Annual Report, Voluntary Dissolution, Revoked, Merged) | C6: Solo prospectar entidades Active; Inactive recientes = empresas desorganizadas (posible servicio) | D6: https://search.sunbiz.org/
A7: Sunbiz – Annual Report | B7: Vence 1 de mayo; LLC $138.75; recargo $400 (Corp/LLC/LP), no condonable | C7: Pico de disoluciones administrativas en la 4.ª semana de septiembre | D7: https://dos.fl.gov/sunbiz/manage-business/efile/annual-report/
A8: Sunbiz – datos públicos | B8: Document No., FEI/EIN, fecha, estado, dirección, registered agent, officers, historial | C8: Nombre del officer = decisor para contacto B2B | D8: https://dos.fl.gov/sunbiz/search/
A9: Sunbiz – descargas masivas | B9: SFTP sftp.floridados.gov: trimestral (todas las activas) y diario (nuevas altas), ancho fijo | C9: Fuente para lead-gen automatizado de empresas nuevas (siguiente fase) | D9: https://dos.fl.gov/sunbiz/other-services/data-downloads/
A10: DBPR – licencias | B10: Contratistas (CILB), hoteles y restaurantes, real estate, cosmetología, CPA, etc. 1.6M+ licenciatarios | C10: Cruzar licencia activa = negocio operativo y regulado | D10: https://www2.myfloridalicense.com/services-requiring-a-dbpr-license/
A11: BTR Miami-Dade | B11: Por local y clasificación; ciudad + condado; año fiscal 1 oct–30 sep | C11: Dataset abierto 'Local Business Tax – View' para prospección por dirección | D11: https://www.mdctaxcollector.gov/services/local-business-tax-receipt
A12: BTR Broward | B12: Obligatorio; renovación 1 jul–30 sep; tarifa por tipo y empleados | C12: Dataset 'Business Tax Records' en Broward GeoHub | D12: https://browardtax.org/business-tax-receipt/
A13: BTR/CU Fort Lauderdale | B13: BTR municipal obligatorio antes de operar (Sec. 15-28) | C13: Validar negocio operativo | D13: https://www.fortlauderdale.gov/Government/Departments/Community-Services/Business-Tax
A14: BTR/CU Miami Beach | B14: Certificate of Use + inspección bomberos + BTR | C14: Validar negocio operativo | D14: https://www.miamibeachfl.gov/city-hall/finance/business-tax-receipts-btr/
A15: BTR/CU Medley | B15: Sin CU no hay BTR; CU municipal exige CU del condado | C15: Validar negocio operativo | D15: https://www.townofmedley.com/local-business-tax-receipts
... A21: ADA web (Title III) | B21: Florida: 1,823 demandas ADA Title III en 2025 (2.º de EE.UU.); ~950 digitales (24%) | C21: Argumento de venta: sitio accesible (WCAG 2.2 AA) reduce riesgo legal | D21: https://www.adatitleiii.com/2026/02/ada-title-iii-federal-lawsuit-filings-fall-slightly-to-8667-in-2025/
A23: Portales de datos abiertos para escalar la base de prospectos
A24: Miami-Dade Open Data – Local Business Tax View | D24: https://opendata.miamidade.gov/datasets/local-business-tax-view
A25: Miami-Dade – Certificates of Use | D25: https://gis-mdc.opendata.arcgis.com/datasets/1952228619b0463cb6f9f7dc839bff88
A26: Broward GeoHub – Business Tax Records | D26: https://geohub-bcgis.opendata.arcgis.com/datasets/business-tax-records/about
A27: Sunbiz – descargas masivas (SFTP) | D27: https://dos.fl.gov/sunbiz/other-services/data-downloads/
A28: DBPR – búsqueda de licencias | D28: https://www2.myfloridalicense.com/

Sheet Metodologia
A1: Metodología, alcance y limitaciones
A2: Investigación de escritorio con fuentes públicas gratuitas. Fecha de corte: septiembre 2026.
A4: Tema | B4: Detalle
A5: Objetivo | B5: Identificar empresas medianas/establecidas en Miami-Dade y Broward (Fort Lauderdale, Kendall, Miami Beach, Medley, Doral, Hialeah, Homestead y alrededores) sin sitio web, con sitio obsoleto o con presencia digital fragmentada.
A6: Fuentes | B6: Census (QuickFacts, CBP, ABS, BFS), Florida Division of Corporations (Sunbiz), DBPR, tax collectors de Miami-Dade y Broward, sitios municipales, FDACS, FTC, Florida Senate; directorios públicos (BBB, Manta, Yelp, YellowPages, D&B, Bizapedia); benchmarks WordStream/LocaliQ.
A7: Criterio estado web | B7: Sin sitio web = ningún dominio propio en resultados de búsqueda. Sitio obsoleto = señales técnicas (http sin HTTPS, .html estático, plantilla sin personalizar, erratas). Presencia desordenada = varios dominios/fichas duplicadas. Tiene web (auditar) = dominio propio, calidad no auditada.
A8: Limitación 1 | B8: El estado web se infirió de fragmentos de búsqueda, no de visitas a cada sitio. Verificar antes de contactar.
A9: Limitación 2 | B9: Forma legal inferida del sufijo del nombre (Inc/LLC/Corp) salvo que se indique Sunbiz. Columna 'Estado Sunbiz' queda 'Pendiente' para validación manual en search.sunbiz.org.
A10: Limitación 3 | B10: Empleados y ventas = estimaciones de Manta/D&B. Establecimientos 20–499 empleados por condado = estimado con proporciones nacionales.
A11: Limitación 4 | B11: Muestra: 95 empresas (no censo). Sesgo hacia industrias con presencia en directorios. Cobertura baja en Miami Beach, Wynwood, restaurantes y salud.
A12: Siguiente fase | B12: Descargar datasets BTR (Miami-Dade, Broward) + archivo trimestral Sunbiz → cruzar por dirección → verificar dominio automáticamente (DNS/HTTP) → escalar a miles de prospectos con estado web medido.
